2025-03-01 16:39:44,262 - exception_logger - ERROR - Exception occured
Traceback (most recent call last):
  File "C:\Users\Jawad\AppData\Local\Temp\ipykernel_3444\2855457381.py", line 12, in log_exception
    1/0
    ~^~
ZeroDivisionError: division by zero
